Workbook

Sheet Estructura 2022
A1: code | B1: NOMBRE | C1: Participacion
A2: C | B2: Industrias manufactureras | C2: 1
A3: 1010 | B3: Elaboración y conservación de carne de ganado bovino | C3: 0.021978962
B4: Carne y despojos comestibles de ganado bovino | C4: 0.021047241
A5: 21111 | B5: Carne de ganado bovino, fresca o refrigerada
A6: 1010 | B6: Elaboración y conservación de carne de ganado porcino | C6: 0.0063594218
B7: Carne de cerdo, fresca o refrigerada | C7: 0.0048080622
A8: 21113 | B8: Carne de cerdo, fresca o refrigerada
B9: Carne y despojos de otros animales y conservas y preparados de carne | C9: 0.00064850992
A10: 21119 | B10: Otras carnes de mamíferos, fresca o refrigerada
A11: 1010 | B11: Elaboración y conservación de carne de aves de corral | C11: 0.034992012
B12: Carne de pollo, fresca o refrigerada | C12: 0.033395838
A13: 21121 | B13: Carne de pollo, fresca o refrigerada
A14: 1010 | B14: Elaboración de productos cárnicos y elaboración de otros productos de origen animal n.c.p. | C14: 0.011484768
B15: Carne y despojos de otros animales y conservas y preparados de carne | C15: 0.010878805
A16: 21174 | B16: Embutidos y productos similares de carne, despojos o sangre
A17: 1020 | B17: Elaboración y conservación de pescado, crustáceos y moluscos | C17: 0.003384264
B18: Crustáceos, congelados | C18: 0.0016903982
A19: 21250 | B19: Crustáceos, congelados
B20: Pescado congelado (excepto filetes y carne de pescado) | C20: 0.0016861472
A21: 21221 | B21: Filetes y carne de pescado (este o no picada), frescos o refrigerados
A22: 1030 | B22: Elaboración y conservación de frutas, legumbres y hortalizas | C22: 0.016134765
B23: Jugos de frutas | C23: 0.0053047974
A24: 21431 | B24: Jugo de naranja
A25: 21435 | B25: Jugo de manzana
A26: 21439 | B26: Otros jugos de frutas, n.c.p.
B27: Vegetales preparados o en conserva, legumbres y papas | C27: 0.0038072431
A28: 21311 | B28: Frijoles estén o no desenvainados, cocidos en agua o vapor, Congelados.
A29: 21395 | B29: Frijoles, preparados o conservados, sin congelar. (excepto en vinagre o ácido acético).
A30: 21399 | B30: Otros vegetales y legumbres, conservados por algo que no sea vinagre, ácido acético o azúcar, n.c.p.
B31: Otras frutas y nueces preparadas y preservadas (excepto por azúcar) | C31: 0.0029615019
A32: 21491 | B32: Piñas, preparadas o conservados
A33: 21492 | B33: Melocotones, preparados o conservados
A34: 21493 | B34: Otras frutas, sin cocer o cocidos, congelados
A35: 21494 | B35: Compotas, jaleas y mermeladas, purés y pastas de frutas u otros frutos
A36: 21495 | B36: Mantequilla de maní, pastas de almendra y otras mezclas de nueces y semillas tosdados, salados o preparados de otro modo n.c.p
A37: 21499 | B37: Otras preparaciones y conservas de frutas y nueces, n.c.p.
B38: Bebidas no alcohólicas | C38: 0.0018334673
A39: 24490 | B39: Otras bebidas calóricas no alcohólicas (Bebidas gaseosas, jugos y refrescos artificiales, bebidas deportivas, agua mineral con sabor)
A40: 24410 | B40: Aguas embotelladas, no endulzadas ni saborizadas (Agua pura, agua con gas o mineral sin sabor, hielo)
...

Sheet Sheet1
A1: SECCIÓN | B1: NAEG | C1: NPG | E1: PRODUCCIÓN | F1: ESTRUCTURA % | H1: VALOR AGREGADO
A2: C | B2: Industrias manufactureras | E2: 300555.93 | H2: 114528.68
A3: C | B3: AE029 | C3: Elaboración y conservación de carne de ganado bovino | E3: 10458.775 | F3: 100 | H3: 2643.0859 | I3: =H3/SUM($H$3:$H$129) -> 0.023077939
B4: AE029 | C4: P2101 | D4: Carne y despojos comestibles de ganado bovino | E4: 10035.109 | F4: 95.94918
A5: C | B5: AE030 | C5: Elaboración y conservación de carne de ganado porcino | E5: 2605.0246 | F5: 100 | H5: 741.48977 | I5: =H5/SUM($H$3:$H$129) -> 0.0064742716
B6: AE030 | C6: P2102 | D6: Carne y despojos comestibles de ganado porcino | E6: 2016.116 | F6: 77.393356
B7: AE030 | C7: P2104 | D7: Carne y despojos de otros animales y conservas y preparados de carne | E7: 252.08292 | F7: 9.676796
A8: C | B8: AE031 | C8: Elaboración y conservación de carne de aves de corral | E8: 15467.354 | F8: 100 | H8: 4111.6386 | I8: =H8/SUM($H$3:$H$129) -> 0.035900516
B9: AE031 | C9: P2103 | D9: Carne y despojos comestibles de aves | E9: 14776.509 | F9: 95.533526
A10: C | B10: AE032 | C10: Elaboración de productos cárnicos y elaboración de otros productos de origen animal n.c.p. | E10: 4078.4026 | F10: 100 | H10: 1292.2178 | I10: =H10/SUM($H$3:$H$129) -> 0.011282919
B11: AE032 | C11: P2104 | D11: Carne y despojos de otros animales y conservas y preparados de carne | E11: 3855.8572 | F11: 94.543321
A12: C | B12: AE033 | C12: Elaboración y conservación de pescado, crustáceos y moluscos | E12: 1035.5425 | F12: 100 | H12: 206.78166 | I12: =H12/SUM($H$3:$H$129) -> 0.0018055011
B13: AE033 | C13: P2202 | D13: Crustáceos, muloscos y demás invertebrados acuáticos congelados, preparados o en conserva y sus productos | E13: 535.86857 | F13: 51.74762
B14: AE033 | C14: P2201 | D14: Pescado congelado, preparado o en conserva y sus productos | E14: 496.99621 | F14: 47.993803
A15: C | B15: AE034 | C15: Elaboración y conservación de frutas, legumbres y hortalizas | E15: 6290.5468 | F15: 100 | H15: 1807.0939 | I15: =H15/SUM($H$3:$H$129) -> 0.015778527
B16: AE034 | C16: P2303 | D16: Jugos de frutas | E16: 2120.4018 | F16: 33.707751
B17: AE034 | C17: P2301 | D17: Vegetales preparados o en conserva, legumbres y papas | E17: 1449.3082 | F17: 23.039463
B18: AE034 | C18: P2304 | D18: Otras frutas y nueces preparadas y preservadas (excepto por azúcar) | E18: 1134.638 | F18: 18.037192
B19: AE034 | C19: P3401 | D19: Bebidas no alcohólicas | E19: 731.76903 | F19: 11.632837
A20: C | B20: AE035 | C20: Elaboración de aceites y grasas de origen vegetal y animal | E20: 15643.131 | F20: 100 | H20: 5985.524 | I20: =H20/SUM($H$3:$H$129) -> 0.052262228
B21: AE035 | C21: P2401 | D21: Aceites de origen vegetal | E21: 12582.036 | F21: 80.431699
A22: C | B22: AE036 | C22: Elaboración de productos lácteos | E22: 5704.0685 | F22: 100 | H22: 2423.5003 | I22: =H22/SUM($H$3:$H$129) -> 0.021160641
B23: AE036 | C23: P2503 | D23: Otros productos lácteos n.c.p. | E23: 3833.6388 | F23: 67.20885
B24: AE036 | C24: P2501 | D24: Leche líquida y crema procesadas | E24: 1815.5239 | F24: 31.828578
A25: C | B25: AE037 | C25: Elaboración de harina de trigo | E25: 4078.0057 | F25: 100 | H25: 1353.0552 | I25: =H25/SUM($H$3:$H$129) -> 0.011814117
B26: AE037 | C26: P2601 | D26: Harina de trigo | E26: 3554.1725 | F26: 87.154673
A27: C | B27: AE038 | C27: Beneficios de arroz | E27: 1694.4917 | F27: 100 | H27: 886.72013 | I27: =H27/SUM($H$3:$H$129) -> 0.0077423414
B28: AE038 | C28: P2602 | D28: Arroz sin cáscara | E28: 1085.1922 | F28: 64.042346
B29: AE038 | C29: P2603 | D29: Otros productos de molinería n.c.p. | E29: 424.92148 | F29: 25.076635
A30: C | B30: AE039 | C30: Elaboración de otros productos de molinería n.c.p. por cuenta propia | E30: 2608.9433 | F30: 100 | H30: 1103.8417 | I30: =H30/SUM($H$3:$H$129) -> 0.0096381247
B31: AE039 | C31: P2603 | D31: Otros productos de molinería n.c.p. | E31: 1992.2122 | F31: 76.360884
B32: AE039 | C32: P3101 | D32: Productos alimenticios n.c.p. | E32: 367.22096 | F32: 14.075467
A33: C | B33: AE040 | C33: Elaboración de almidones y productos derivados del almidón | E33: 2299.0025 | F33: 100 | H33: 1371.7755 | I33: =H33/SUM($H$3:$H$129) -> 0.011977572
B34: AE040 | C34: P6212 | D34: Servicios de manufactura | E34: 2226.3365 | F34: 96.839237
A35: C | B35: AE041 | C35: Elaboración de productos de panadería | E35: 13772.924 | F35: 100 | H35: 6438.0078 | I35: =H35/SUM($H$3:$H$129) -> 0.056213063
B36: AE041 | C36: P2701 | D36: Pan | E36: 10902.946 | F36: 79.162174
B37: AE041 | C37: P2702 | D37: Otros productos de panadería y repostería n.c.p. | E37: 2681.7031 | F37: 19.470834
A38: C | B38: AE042 | C38: Elaboración de tortillas de maíz | E38: 11657.461 | F38: 100 | H38: 6276.0968 | I38: =H38/SUM($H$3:$H$129) -> 0.054799347
B39: AE042 | C39: P2703 | D39: Tortillas de maíz, incluso tostadas, horneadas o fritas | E39: 11596.062 | F39: 99.473306
A40: C | B40: AE043 | C40: Elaboración de azúcar | E40: 14046.281 | F40: 100 | H40: 4163.3267 | I40: =H40/SUM($H$3:$H$129) -> 0.036351827
...

Sheet Base_revision
A1: Seccion | B1: NAEG | C1: Nombre/NPG | D1: Nom_prod | E1: VALOR | F1: Participacion | G1: VAB | N1: VAB2022 | O1: VAB2023 | Q1: VBP2022 | R1: VBP2023 | T1: SECCIÓN | U1: NAEG | V1: NPG/NombreNAEG | W1: Glosa_NPG | X1: VAB2022 | Y1: PRODUCCIÓN | Z1: ESTRUCTURA % | AA1: Porcentaje VBP | AB1: CIIU correl | AC1: CIIU_Clase | AD1: code | AE1: NOMBRE | AF1: Participacion 2022 | AG1: Partic. 2023 VAB | AH1: Participacion 2023
A2: C | B2: AE029 | C2: Elaboración y conservación de carne de ganado bovino | E2: 10458.775 | F2: 100 | G2: =VLOOKUP(B2,$L$2:$N$122,3,FALSE) -> 765.90094 | L2: AE029 | M2: Elaboración y conservación de carne de ganado bovino | N2: 765.90094 | O2: 444.21099 | P2: AE029 | Q2: 1520.3302 | R2: 1128.3402 | T2: C | U2: Industrias manufactureras | X2: 104349.64 | Y2: 290729.35 | AB2: C | AD2: C | AE2: Industrias manufactureras
B3: AE029 | C3: P2101 | D3: Carne y despojos comestibles de ganado bovino | E3: 10035.109 | F3: 95.94918 | L3: AE030 | M3: Elaboración y conservación de carne de ganado porcino | N3: 2080.9968 | O3: 1405.3571 | P3: AE030 | Q3: 4458.0413 | R3: 3320.5905 | T3: C | U3: AE029 | V3: Elaboración y conservación de carne de ganado bovino | X3: =VLOOKUP(U3,'[1]% SECCION_ECONOMIA 2022'!$C$81:$I$209,7,FALSE) -> 2293.4968 | Y3: 9298.8396 | Z3: 100 | AA3: =X3/$X$2 -> 0.021978962 | AB3: 10101 | AC3: =LEFT(AB3,4) -> 1010 | AD3: 1010 | AE3: Elaboración y conservación de carne de ganado bovino | AF3: =AN3 -> 0.022185477 | AG3: =VLOOKUP(U3,Sheet1!$B$3:$I$129,8,FALSE) -> 0.023077939 | AH3: =AG3 -> 0.023077939 | AI3: =AG3/AF3-1 -> 0.040227292 | AL3: 1010 | AM3: Elaboración y conservación de carne de ganado bovino | AN3: 0.022185477
A4: C | B4: AE030 | C4: Elaboración y conservación de carne de ganado porcino | E4: 2605.0246 | F4: 100 | G4: =VLOOKUP(B4,$L$2:$N$122,3,FALSE) -> 2080.9968 | L4: AE031 | M4: Elaboración y conservación de carne de aves de corral | N4: 5985.6467 | O4: 3899.5348 | P4: AE031 | Q4: 12936.486 | R4: 9683.78 | U4: AE029 | V4: P2101 | W4: Carne y despojos comestibles de ganado bovino | Y4: 8904.6478 | Z4: 95.760849 | AC4: =LEFT(AB4,4) | AE4: Carne y despojos comestibles de ganado bovino | AF4: =Z4*AF3/100 -> 0.021245002 | AG4: =VLOOKUP(V4,Sheet1!$C$4:$F$131,4,FALSE) -> 95.94918 | AH4: =AG4*AH3/100 -> 0.022143093 | AI4: =AH4/AF4-1 -> 0.042273086
AD5: 21111 | AE5: Carne de ganado bovino, fresca o refrigerada | AF5: =AF4/AF4*AF3 -> 0.022185477 | AH5: =AH4/AH4*AH3 -> 0.023077939
B6: AE030 | C6: P2102 | D6: Carne y despojos comestibles de ganado porcino | E6: 2016.116 | F6: 77.393356 | L6: AE032 | M6: Elaboración de productos cárnicos y elaboración de otros productos de origen animal n.c.p. | N6: 5629.0697 | O6: 3473.9102 | P6: AE032 | Q6: 10633.25 | R6: 7007.7888 | T6: C | U6: AE030 | V6: Elaboración y conservación de carne de ganado porcino | X6: =VLOOKUP(U6,'[1]% SECCION_ECONOMIA 2022'!$C$81:$I$209,7,FALSE) -> 663.6034 | Y6: 2340.483 | Z6: 100 | AA6: =X6/$X$2 -> 0.0063594218 | AB6: 10102 | AC6: =LEFT(AB6,4) -> 1010 | AD6: 1010 | AE6: =V6 -> Elaboración y conservación de carne de ganado porcino | AF6: =AN6 -> 0.0064191753 | AG6: =VLOOKUP(U6,Sheet1!$B$3:$I$129,8,FALSE) -> 0.0064742716 | AH6: =AG6 -> 0.0064742716 | AI6: =AG6/AF6-1 -> 0.0085830723 | AL6: 1010 | AM6: Elaboración y conservación de carne de ganado porcino | AN6: 0.0064191753
B7: AE030 | C7: P2104 | D7: Carne y despojos de otros animales y conservas y preparados de carne | E7: 252.08292 | F7: 9.676796 | L7: AE033 | M7: Elaboración y conservación de pescado, crustáceos y moluscos | N7: 4028.7624 | O7: 4376.0591 | P7: AE033 | Q7: 13926.703 | R7: 12985.049 | U7: AE030 | V7: P2102 | W7: Carne y despojos comestibles de ganado porcino | Y7: 1769.53 | Z7: 75.605335 | AE7: Carne de cerdo, fresca o refrigerada | AF7: =Z7*AF6/100 -> 0.004853239 | AG7: =VLOOKUP(V7,Sheet1!$C$4:$F$131,4,FALSE) -> 77.393356 | AH7: =AG7*AH6/100 -> 0.0050106561 | AI7: =AH7/AF7-1 -> 0.03243546
AD8: 21113 | AE8: Carne de cerdo, fresca o refrigerada | AF8: =AF7/($AH$7+$AH$9)*$AH$6 -> 0.0055739411 | AH8: =AH7/($AH$7+$AH$9)*$AH$6 -> 0.0057547345
A9: C | B9: AE031 | C9: Elaboración y conservación de carne de aves de corral | E9: 15467.354 | F9: 100 | G9: =VLOOKUP(B9,$L$2:$N$122,3,FALSE) -> 5985.6467 | L9: AE034 | M9: Elaboración y conservación de frutas, legumbres y hortalizas | N9: 4160.0959 | O9: 3250.5095 | P9: AE034 | Q9: 11398.973 | R9: 8637.0781 | U9: AE030 | V9: P2104 | W9: Carne y despojos de otros animales y conservas y preparados de carne | Y9: 238.67365 | Z9: 10.197624 | AE9: Carne y despojos de otros animales y conservas y preparados de carne | AF9: =Z9*AF6/100 -> 0.00065460336 | AG9: =VLOOKUP(V9,Sheet1!$C$4:$F$131,4,FALSE) -> 9.676796 | AH9: =AG9*AH6/100 -> 0.00062650205 | AI9: =AH9/AF9-1 -> -0.042928755
AD10: 21119 | AE10: Otras carnes de mamíferos, fresca o refrigerada | AF10: =AF9/($AH$7+$AH$9)*$AH$6 -> 0.00075181143 | AH10: =AH9/($AH$7+$AH$9)*$AH$6 -> 0.0007195371
B11: AE031 | C11: P2103 | D11: Carne y despojos comestibles de aves | E11: 14776.509 | F11: 95.533526 | L11: AE035 | M11: Elaboración de aceites y grasas de origen vegetal y animal | N11: 2724.8798 | O11: 1628.3915 | P11: AE035 | Q11: 7267.5922 | R11: 5179.4898 | T11: C | U11: AE031 | V11: Elaboración y conservación de carne de aves de corral | X11: =VLOOKUP(U11,'[1]% SECCION_ECONOMIA 2022'!$C$81:$I$209,7,FALSE) -> 3651.404 | Y11: 13487.919 | Z11: 100 | AA11: =X11/$X$2 -> 0.034992012 | AB11: 10103 | AC11: =LEFT(AB11,4) -> 1010 | AD11: 1010 | AE11: =V11 -> Elaboración y conservación de carne de aves de corral | AF11: =AN11 -> 0.035320799 | AG11: =VLOOKUP(U11,Sheet1!$B$3:$I$129,8,FALSE) -> 0.035900516 | AH11: =AG11 -> 0.035900516 | AI11: =AG11/AF11-1 -> 0.016412887 | AL11: 1010 | AM11: Elaboración y conservación de carne de aves de corral | AN11: 0.035320799
A12: C | B12: AE032 | C12: Elaboración de productos cárnicos y elaboración de otros productos de origen animal n.c.p. | E12: 4078.4026 | F12: 100 | G12: =VLOOKUP(B12,$L$2:$N$122,3,FALSE) -> 5629.0697 | L12: AE036 | M12: Elaboración de productos lácteos | N12: 1049.2953 | O12: 1186.8928 | P12: AE036 | Q12: 4382.6725 | R12: 3887.7555 | U12: AE031 | V12: P2103 | W12: Carne y despojos comestibles de aves | Y12: 12872.663 | Z12: 95.438459 | AE12: Carne de pollo, fresca o refrigerada | AF12: =Z12*AF11/100 -> 0.033709627 | AG12: =VLOOKUP(V12,Sheet1!$C$4:$F$131,4,FALSE) -> 95.533526 | AH12: =AG12*AH11/100 -> 0.034297029 | AI12: =AH12/AF12-1 -> 0.017425343
AD13: 21121 | AE13: Carne de pollo, fresca o refrigerada | AF13: =AF12/AF12*AF11 -> 0.035320799 | AH13: =AH12/AH12*AH11 -> 0.035900516
AD14: 21160 | AE14: Despojos comestibles de aves de corral, frescos, refrigerados o congelados
B15: AE032 | C15: P2104 | D15: Carne y despojos de otros animales y conservas y preparados de carne | E15: 3855.8572 | F15: 94.543321 | L15: AE037 | M15: Elaboración de harina de trigo | N15: 3733.6507 | O15: 3835.9226 | P15: AE037 | Q15: 14340.219 | R15: 12242.223 | T15: C | U15: AE032 | V15: Elaboración de productos cárnicos y elaboración de otros productos de origen animal n.c.p. | X15: =VLOOKUP(U15,'[1]% SECCION_ECONOMIA 2022'!$C$81:$I$209,7,FALSE) -> 1198.4314 | Y15: 3804.6624 | Z15: 100 | AA15: =X15/$X$2 -> 0.011484768 | AB15: 10104 | AC15: =LEFT(AB15,4) -> 1010 | AD15: 1010 | AE15: =V15 -> Elaboración de productos cárnicos y elaboración de otros productos de origen animal n.c.p. | AF15: =AN15 -> 0.011592679 | AG15: =VLOOKUP(U15,Sheet1!$B$3:$I$129,8,FALSE) -> 0.011282919 | AH15: =AG15 -> 0.011282919 | AI15: =AG15/AF15-1 -> -0.026720315 | AL15: 1010 | AM15: Elaboración de productos cárnicos y elaboración de otros productos de origen animal n.c.p. | AN15: 0.011592679
A16: C | B16: AE033 | C16: Elaboración y conservación de pescado, crustáceos y moluscos | E16: 1035.5425 | F16: 100 | G16: =VLOOKUP(B16,$L$2:$N$122,3,FALSE) -> 4028.7624 | L16: AE038 | M16: Beneficios de arroz | N16: 2833.2948 | O16: 2639.9503 | P16: AE038 | Q16: 8376.4913 | R16: 7282.1213 | U16: AE032 | V16: P2104 | W16: Carne y despojos de otros animales y conservas y preparados de carne | Y16: 3603.9197 | Z16: 94.723771 | AE16: =W16 -> Carne y despojos de otros animales y conservas y preparados de carne | AF16: =AF15*Z16/100 -> 0.010981023 | AG16: =Sheet1!F11 -> 94.543321 | AH16: =AG16*AH15/100 -> 0.010667246 | AI16: =AH16/AF16-1 -> -0.02857443
AD17: 21174 | AE17: Embutidos y productos similares de carne, despojos o sangre | AF17: =AF16/AF16*AF15 -> 0.011592679 | AH17: =AH16/AH16*AH15 -> 0.011282919
B18: AE033 | C18: P2202 | D18: Crustáceos, muloscos y demás invertebrados acuáticos congelados, preparados o en conserva y sus productos | E18: 535.86857 | F18: 51.74762 | L18: AE039 | M18: Elaboración de otros productos de molinería n.c.p. por cuenta propia | N18: 7713.446 | O18: 6923.9233 | P18: AE039 | Q18: 16131.452 | R18: 14159.957 | T18: C | U18: AE033 | V18: Elaboración y conservación de pescado, crustáceos y moluscos | X18: =VLOOKUP(U18,'[1]% SECCION_ECONOMIA 2022'!$C$81:$I$209,7,FALSE) -> 353.14675 | Y18: 1491.6421 | Z18: 100 | AA18: =X18/$X$2 -> 0.003384264 | AB18: 1020 | AC18: =LEFT(AB18,4) -> 1020 | AD18: 1020 | AE18: =V18 -> Elaboración y conservación de pescado, crustáceos y moluscos | AF18: =AN18 -> 0 | AG18: =VLOOKUP(U18,Sheet1!$B$3:$I$129,8,FALSE) -> 0.0018055011 | AH18: =AG18 -> 0.0018055011 | AI18: =AG18/AF18-1 -> #DIV/0! | AL18: 1020 | AM18: Elaboración y conservación de pescado, crustáceos y moluscos
B19: AE033 | C19: P2201 | D19: Pescado congelado, preparado o en conserva y sus productos | E19: 496.99621 | F19: 47.993803 | L19: AE040 | M19: Elaboración de almidones y productos derivados del almidón | N19: 1035.9504 | O19: 972.96677 | P19: AE040 | Q19: 2937.5552 | R19: 2615.2248 | U19: AE033 | V19: P2202 | W19: Crustáceos, muloscos y demás invertebrados acuáticos congelados, preparados o en conserva y sus productos | Y19: 745.05686 | Z19: 49.948768 | AE19: Crustáceos, congelados | AF19: =Z19*AA18/100 -> 0.0016903982 | AG19: =VLOOKUP(V19,Sheet1!$C$4:$F$131,4,FALSE) -> 51.74762 | AH19: =AG19*AH18/100 -> 0.00093430386 | AI19: =AH19/AF19-1 -> -0.44728771
AD20: 21250 | AE20: Crustáceos, congelados | AF20: =(AF19/($AF$19+$AF$21)*$AF$18) -> 0 | AH20: =(AH19/($AH$19+$AH$21)*$AH$18) -> 0.00093672602
A21: C | B21: AE034 | C21: Elaboración y conservación de frutas, legumbres y hortalizas | E21: 6290.5468 | F21: 100 | G21: =VLOOKUP(B21,$L$2:$N$122,3,FALSE) -> 4160.0959 | L21: AE041 | M21: Elaboración de productos de panadería | N21: 2026.4841 | O21: 1277.2967 | P21: AE041 | Q21: 5287.0732 | R21: 3701.5394 | U21: AE033 | V21: P2201 | W21: Pescado congelado, preparado o en conserva y sus productos | Y21: 743.18318 | Z21: 49.823157 | AE21: Pescado congelado (excepto filetes y carne de pescado) | AF21: =Z21*AF18/100 -> 0 | AG21: =VLOOKUP(V21,Sheet1!$C$4:$F$131,4,FALSE) -> 47.993803 | AH21: =AG21*AH18/100 -> 0.00086652865 | AI21: =AH21/AF21-1 -> #DIV/0!
AD22: 21221 | AE22: Filetes y carne de pescado (este o no picada), frescos o refrigerados | AF22: =(AF21/($AF$19+$AF$21)*$AF$18) -> 0 | AH22: =(AH21/($AH$19+$AH$21)*$AH$18) -> 0.00086877511
B23: AE034 | C23: P2303 | D23: Jugos de frutas | E23: 2120.4018 | F23: 33.707751 | L23: AE042 | M23: Elaboración de tortillas de maíz | N23: 2599.6731 | O23: 1887.997 | P23: AE042 | Q23: 8977.2816 | R23: 6610.9112 | T23: C | U23: AE034 | V23: Elaboración y conservación de frutas, legumbres y hortalizas | X23: =VLOOKUP(U23,'[1]% SECCION_ECONOMIA 2022'!$C$81:$I$209,7,FALSE) -> 1683.6569 | Y23: 5901.3352 | Z23: 100 | AA23: =X23/$X$2 -> 0.016134765 | AB23: 1030 | AC23: =LEFT(AB23,4) -> 1030 | AD23: 1030 | AE23: =V23 -> Elaboración y conservación de frutas, legumbres y hortalizas | AF23: =AN23 -> 0.016286368 | AG23: =VLOOKUP(U23,Sheet1!$B$3:$I$129,8,FALSE) -> 0.015778527 | AH23: =AG23 -> 0.015778527 | AI23: =AG23/AF23-1 -> -0.031181942 | AL23: 1030 | AM23: Elaboración y conservación de frutas, legumbres y hortalizas | AN23: 0.016286368
B24: AE034 | C24: P2301 | D24: Vegetales preparados o en conserva, legumbres y papas | E24: 1449.3082 | F24: 23.039463 | L24: AE043 | M24: Elaboración de azúcar | N24: 974.77201 | O24: 1030.6753 | P24: AE043 | Q24: 2875.8252 | R24: 2496.3436 | U24: AE034 | V24: P2303 | W24: Jugos de frutas | Y24: 1940.2445 | Z24: 32.878059 | AE24: Jugos de frutas | AF24: =Z24*AF23/100 -> 0.0053546416 | AG24: =VLOOKUP(V24,Sheet1!$C$4:$F$131,4,FALSE) -> 33.707751 | AH24: =AG24*AH23/100 -> 0.0053185867 | AI24: =AH24/AF24-1 -> -0.0067333969
AD25: 21431 | AE25: Jugo de naranja | AF25: =(AF24/($AF$24+$AF$28+$AF$32+$AF$39)*$AF$23) -> 0.0062123982 | AH25: =(AH24/($AH$24+$AH$28+$AH$32+$AH$39)*$AH$23) -> 0.0061545434
AD26: 21435 | AE26: Jugo de manzana
AD27: 21439 | AE27: Otros jugos de frutas, n.c.p.
B28: AE034 | C28: P2304 | D28: Otras frutas y nueces preparadas y preservadas (excepto por azúcar) | E28: 1134.638 | F28: 18.037192 | L28: AE044 | M28: Elaboración de cacao y chocolate y de productos de confitería | N28: 3265.1852 | O28: 2073.0569 | P28: AE044 | Q28: 7866.4176 | R28: 5264.2734 | U28: AE034 | V28: P2301 | W28: Vegetales preparados o en conserva, legumbres y papas | Y28: 1392.5098 | Z28: 23.596521 | AE28: =W28 -> Vegetales preparados o en conserva, legumbres y papas | AF28: =Z28*AF$23/100 -> 0.0038430161 | AG28: =VLOOKUP(V28,Sheet1!$C$4:$F$131,4,FALSE) -> 23.039463 | AH28: =AG28*AH23/100 -> 0.0036352879 | AI28: =AH28/AF28-1 -> -0.054053427
AD29: 21311 | AE29: Frijoles estén o no desenvainados, cocidos en agua o vapor, Congelados. | AF29: =(AF28/($AF$24+$AF$28+$AF$32+$AF$39)*$AF$23) -> 0.0044586264 | AH29: =(AH28/($AH$24+$AH$28+$AH$32+$AH$39)*$AH$23) -> 0.0042066697
AD30: 21395 | AE30: Frijoles, preparados o conservados, sin congelar. (excepto en vinagre o ácido acético).
AD31: 21399 | AE31: Otros vegetales y legumbres, conservados por algo que no sea vinagre, ácido acético o azúcar, n.c.p.
B32: AE034 | C32: P3401 | D32: Bebidas no alcohólicas | E32: 731.76903 | F32: 11.632837 | L32: AE045 | M32: Elaboración de macarrones, fideos, alcuzcuz y productos farináceos similares | N32: 2797.5387 | O32: 2555.9811 | P32: AE045 | Q32: 7377.2439 | R32: 6103.8861 | U32: AE034 | V32: P2304 | W32: Otras frutas y nueces preparadas y preservadas (excepto por azúcar) | Y32: 1083.1776 | Z32: 18.354788 | AE32: =W32 -> Otras frutas y nueces preparadas y preservadas (excepto por azúcar) | AF32: =Z32*AF$23/100 -> 0.0029893283 | AG32: =VLOOKUP(V32,Sheet1!$C$4:$F$131,4,FALSE) -> 18.037192 | AH32: =AG32*AH23/100 -> 0.0028460032 | AI32: =AH32/AF32-1 -> -0.047945576
AD33: 21491 | AE33: Piñas, preparadas o conservados | AF33: =(AF32/($AF$24+$AF$28+$AF$32+$AF$39)*$AF$23) -> 0.0034681869 | AH33: =(AH32/($AH$24+$AH$28+$AH$32+$AH$39)*$AH$23) -> 0.003293328
AD34: 21492 | AE34: Melocotones, preparados o conservados
AD35: 21493 | AE35: Otras frutas, sin cocer o cocidos, congelados
AD36: 21494 | AE36: Compotas, jaleas y mermeladas, purés y pastas de frutas u otros frutos
AD37: 21495 | AE37: Mantequilla de maní, pastas de almendra y otras mezclas de nueces y semillas tosdados, salados o preparados de otro modo n.c.p
AD38: 21499 | AE38: Otras preparaciones y conservas de frutas y nueces, n.c.p.
A39: C | B39: AE035 | C39: Elaboración de aceites y grasas de origen vegetal y animal | E39: 15643.131 | F39: 100 | G39: =VLOOKUP(B39,$L$2:$N$122,3,FALSE) -> 2724.8798 | L39: AE046 | M39: Elaboración de otros productos alimenticios n.c.p incluyendo comidas y platos preparados | N39: 2201.8797 | O39: 1938.7121 | P39: AE046 | Q39: 6160.5907 | R39: 4844.272 | U39: AE034 | V39: P3401 | W39: Bebidas no alcohólicas | Y39: 670.59579 | Z39: 11.363459 | AE39: =W39 -> Bebidas no alcohólicas | AF39: =Z39*AF$23/100 -> 0.0018506947 | AG39: =VLOOKUP(V39,Sheet1!$C$4:$F$131,4,FALSE) -> 11.632837 | AH39: =AG39*AH23/100 -> 0.0018354903 | AI39: =AH39/AF39-1 -> -0.0082154951
AD40: 24490 | AE40: Otras bebidas calóricas no alcohólicas (Bebidas gaseosas, jugos y refrescos artificiales, bebidas deportivas, agua mineral con sabor) | AF40: =(AF39/($AF$24+$AF$28+$AF$32+$AF$39)*$AF$23) -> 0.0021471563 | AH40: =(AH39/($AH$24+$AH$28+$AH$32+$AH$39)*$AH$23) -> 0.0021239862
...

Sheet Sheet2
B1: CIIU_Clase | C1: code | D1: NOMBRE | E1: Participacion 2022 | H1: code | I1: NOMBRE | J1: Participacion 2022
C2: C | D2: Industrias manufactureras | G2: =LEFT(H2,2) -> 10 | H2: 1010 | I2: Elaboración y conservación de carne de ganado bovino | J2: 0.021978962 | K2: =SUM(J2:J20) -> 0.42242306 | L2: =J2/SUM($J$2:$J$5,$J$7:$J$20) -> 0.0524509 | M2: =L2*$K$2 -> 0.02215647 | N2: =M2/$M$56 -> 0.022185477
B3: 1010 | C3: 1010 | D3: Elaboración y conservación de carne de ganado bovino | E3: 0.022185477 | G3: =LEFT(H3,2) -> 10 | H3: 1010 | I3: Elaboración y conservación de carne de ganado porcino | J3: 0.0063594218 | L3: =J3/SUM($J$2:$J$5,$J$7:$J$20) -> 0.015176212 | M3: =L3*$K$2 -> 0.0064107821 | N3: =M3/$M$56 -> 0.0064191753
D4: Carne y despojos comestibles de ganado bovino | E4: 0.021245002 | G4: =LEFT(H4,2) -> 10 | H4: 1010 | I4: Elaboración y conservación de carne de aves de corral | J4: 0.034992012 | L4: =J4/SUM($J$2:$J$5,$J$7:$J$20) -> 0.083505424 | M4: =L4*$K$2 -> 0.035274617 | N4: =M4/$M$56 -> 0.035320799
C5: 21111 | D5: Carne de ganado bovino, fresca o refrigerada | E5: 0.022185477 | G5: =LEFT(H5,2) -> 10 | H5: 1010 | I5: Elaboración de productos cárnicos y elaboración de otros productos de origen animal n.c.p. | J5: 0.011484768 | L5: =J5/SUM($J$2:$J$5,$J$7:$J$20) -> 0.027407409 | M5: =L5*$K$2 -> 0.011577522 | N5: =M5/$M$56 -> 0.011592679
B6: 1010 | C6: 1010 | D6: Elaboración y conservación de carne de ganado porcino | E6: 0.0064191753 | G6: =LEFT(H6,2) -> 10 | H6: 1020 | I6: Elaboración y conservación de pescado, crustáceos y moluscos | J6: 0.003384264
D7: Carne de cerdo, fresca o refrigerada | E7: 0.004853239 | G7: =LEFT(H7,2) -> 10 | H7: 1030 | I7: Elaboración y conservación de frutas, legumbres y hortalizas | J7: 0.016134765 | L7: =J7/SUM($J$2:$J$5,$J$7:$J$20) -> 0.038504226 | M7: =L7*$K$2 -> 0.016265073 | N7: =M7/$M$56 -> 0.016286368
C8: 21113 | D8: Carne de cerdo, fresca o refrigerada | E8: 0.0055739411 | G8: =LEFT(H8,2) -> 10 | H8: 1040 | I8: Elaboración de aceites y grasas de origen vegetal y animal | J8: 0.056363419 | L8: =J8/SUM($J$2:$J$5,$J$7:$J$20) -> 0.13450645 | M8: =L8*$K$2 -> 0.056818624 | N8: =M8/$M$56 -> 0.056893013
D9: Carne y despojos de otros animales y conservas y preparados de carne | E9: 0.00065460336 | G9: =LEFT(H9,2) -> 10 | H9: 1050 | I9: Elaboración de productos lácteos | J9: 0.01921303 | L9: =J9/SUM($J$2:$J$5,$J$7:$J$20) -> 0.045850241 | M9: =L9*$K$2 -> 0.019368199 | N9: =M9/$M$56 -> 0.019393556
C10: 21119 | D10: Otras carnes de mamíferos, fresca o refrigerada | E10: 0.00075181143 | G10: =LEFT(H10,2) -> 10 | H10: 1061 | I10: Elaboración de harina de trigo | J10: 0.0093361974 | L10: =J10/SUM($J$2:$J$5,$J$7:$J$20) -> 0.022280031 | M10: =L10*$K$2 -> 0.0094115989 | N10: =M10/$M$56 -> 0.0094239208
B11: 1010 | C11: 1010 | D11: Elaboración y conservación de carne de aves de corral | E11: 0.035320799 | G11: =LEFT(H11,2) -> 10 | H11: 1061 | I11: Beneficios de arroz | J11: 0.0073397561 | L11: =J11/SUM($J$2:$J$5,$J$7:$J$20) -> 0.017515696 | M11: =L11*$K$2 -> 0.0073990338 | N11: =M11/$M$56 -> 0.0074087209
D12: Carne de pollo, fresca o refrigerada | E12: 0.033709627 | G12: =LEFT(H12,2) -> 10 | H12: 1061 | I12: Elaboración de otros productos de molinería n.c.p. por cuenta propia | J12: 0.0086210164 | L12: =J12/SUM($J$2:$J$5,$J$7:$J$20) -> 0.020573313 | M12: =L12*$K$2 -> 0.0086906419 | N12: =M12/$M$56 -> 0.00870202
C13: 21121 | D13: Carne de pollo, fresca o refrigerada | E13: 0.035320799 | G13: =LEFT(H13,2) -> 10 | H13: 1062 | I13: Elaboración de almidones y productos derivados del almidón | J13: 0.011321522 | L13: =J13/SUM($J$2:$J$5,$J$7:$J$20) -> 0.027017837 | M13: =L13*$K$2 -> 0.011412957 | N13: =M13/$M$56 -> 0.0114279
B14: 1010 | C14: 1010 | D14: Elaboración de productos cárnicos y elaboración de otros productos de origen animal n.c.p. | E14: 0.011592679 | G14: =LEFT(H14,2) -> 10 | H14: 1071 | I14: Elaboración de productos de panadería | J14: 0.057361449 | L14: =J14/SUM($J$2:$J$5,$J$7:$J$20) -> 0.13688816 | M14: =L14*$K$2 -> 0.057824714 | N14: =M14/$M$56 -> 0.05790042
D15: Carne y despojos de otros animales y conservas y preparados de carne | E15: 0.010981023 | G15: =LEFT(H15,2) -> 10 | H15: 1071 | I15: Elaboración de tortillas de maíz | J15: 0.053944312 | L15: =J15/SUM($J$2:$J$5,$J$7:$J$20) -> 0.12873345 | M15: =L15*$K$2 -> 0.05437998 | N15: =M15/$M$56 -> 0.054451176
C16: 21174 | D16: Embutidos y productos similares de carne, despojos o sangre | E16: 0.011592679 | G16: =LEFT(H16,2) -> 10 | H16: 1072 | I16: Elaboración de azúcar | J16: 0.038608301 | L16: =J16/SUM($J$2:$J$5,$J$7:$J$20) -> 0.092135385 | M16: =L16*$K$2 -> 0.038920111 | N16: =M16/$M$56 -> 0.038971067
B17: 1020 | C17: 1020 | D17: Elaboración y conservación de pescado, crustáceos y moluscos | E17: 0 | G17: =LEFT(H17,2) -> 10 | H17: 1073 | I17: Elaboración de cacao y chocolate y de productos de confitería | J17: 0.0063729534 | L17: =J17/SUM($J$2:$J$5,$J$7:$J$20) -> 0.015208504 | M17: =L17*$K$2 -> 0.0064244229 | N17: =M17/$M$56 -> 0.006432834
D18: Crustáceos, congelados | E18: 0.0016903982 | G18: =LEFT(H18,2) -> 10 | H18: 1074 | I18: Elaboración de macarrones, fideos, alcuzcuz y productos farináceos similares | J18: 0.0045227786 | L18: =J18/SUM($J$2:$J$5,$J$7:$J$20) -> 0.010793222 | M18: =L18*$K$2 -> 0.0045593058 | N18: =M18/$M$56 -> 0.0045652749
C19: 21250 | D19: Crustáceos, congelados | E19: 0 | G19: =LEFT(H19,2) -> 10 | H19: 1079 | I19: Elaboración de otros productos alimenticios n.c.p incluyendo comidas y platos preparados | J19: 0.028971159 | L19: =J19/SUM($J$2:$J$5,$J$7:$J$20) -> 0.069137175 | M19: =L19*$K$2 -> 0.029205137 | N19: =M19/$M$56 -> 0.029243373
D20: Pescado congelado (excepto filetes y carne de pescado) | E20: 0 | G20: =LEFT(H20,2) -> 10 | H20: 1080 | I20: Elaboración de alimentos preparados para animales | J20: 0.026112977 | L20: =J20/SUM($J$2:$J$5,$J$7:$J$20) -> 0.062316369 | M20: =L20*$K$2 -> 0.026323872 | N20: =M20/$M$56 -> 0.026358336
C21: 21221 | D21: Filetes y carne de pescado (este o no picada), frescos o refrigerados | E21: 0 | G21: =LEFT(H21,2) -> 11 | H21: 1101 | I21: Destilación, rectificación y mezcla de bebidas alcohólicas | J21: 0.0023082271 | K21: =SUM(J21:J24) -> 0.044528248
B22: 1030 | C22: 1030 | D22: Elaboración y conservación de frutas, legumbres y hortalizas | E22: 0.016286368 | G22: =LEFT(H22,2) -> 11 | H22: 1102 | I22: Elaboración de vinos | J22: 0.00012792913
D23: Jugos de frutas | E23: 0.0053546416 | G23: =LEFT(H23,2) -> 11 | H23: 1103 | I23: Elaboración de bebidas malteadas y de malta | J23: 0.0063118962 | L23: =J23/SUM($J$23:$J$24) -> 0.14995444 | M23: =L23*$K$21 -> 0.0066772087 | N23: =M23/$M$56 -> 0.0066859507
C24: 21431 | D24: Jugo de naranja | E24: 0.0062123982 | G24: =LEFT(H24,2) -> 11 | H24: 1104 | I24: Elaboración de bebidas no alcohólicas; producción de aguas minerales y otras aguas embotelladas | J24: 0.035780195 | L24: =J24/SUM($J$23:$J$24) -> 0.85004556 | M24: =L24*$K$21 -> 0.037851039 | N24: =M24/$M$56 -> 0.037900595
C25: 21435 | D25: Jugo de manzana | G25: =LEFT(H25,2) -> 12 | H25: 1200 | I25: Elaboración de productos de tabaco | J25: 0.0013075191 | K25: =J25 -> 0.0013075191
C26: 21439 | D26: Otros jugos de frutas, n.c.p. | G26: =LEFT(H26,2) -> 13 | H26: 1311 | I26: Hilatura, tejedura y acabado de productos textiles | J26: 0.0096788994 | K26: =SUM(J26:J27) -> 0.027151935 | M26: =J26 -> 0.0096788994 | N26: =M26/$M$56 -> 0.0096915713
D27: Vegetales preparados o en conserva, legumbres y papas | E27: 0.0038430161 | G27: =LEFT(H27,2) -> 13 | H27: 1391 | I27: Fabricación de otros productos textiles | J27: 0.017473036 | M27: =J27 -> 0.017473036 | N27: =M27/$M$56 -> 0.017495912
C28: 21311 | D28: Frijoles estén o no desenvainados, cocidos en agua o vapor, Congelados. | E28: 0.0044586264 | G28: =LEFT(H28,2) -> 14 | H28: 1410 | I28: Fabricación de prendas de vestir | J28: 0.073919236 | K28: =J28 -> 0.073919236 | M28: =J28 -> 0.073919236 | N28: =M28/$M$56 -> 0.074016013
C29: 21395 | D29: Frijoles, preparados o conservados, sin congelar. (excepto en vinagre o ácido acético). | G29: =LEFT(H29,2) -> 15 | H29: 1512 | I29: Curtido, adobo, teñido de cueros y pieles; fabricación de maletas, bolsos de mano y artículos similares, y artículos de talabartería y guarnicionería | J29: 0.0033287319 | K29: =J29+J30 -> 0.009927685
C30: 21399 | D30: Otros vegetales y legumbres, conservados por algo que no sea vinagre, ácido acético o azúcar, n.c.p. | G30: =LEFT(H30,2) -> 15 | H30: 1520 | I30: Fabricación de calzado de cualquier material y de cualquier uso; partes de calzado de cuero | J30: 0.0065989531 | L30: =J30/J30 -> 1 | M30: =L30*K29 -> 0.009927685 | N30: =M30/$M$56 -> 0.0099406826
D31: Otras frutas y nueces preparadas y preservadas (excepto por azúcar) | E31: 0.0029893283 | G31: =LEFT(H31,2) -> 16 | H31: 1610 | I31: Aserrado y acepilladura de madera | J31: 0.011694871 | K31: =J31+J32 -> 0.019420134 | M31: =J31 -> 0.011694871 | N31: =M31/$M$56 -> 0.011710182
C32: 21491 | D32: Piñas, preparadas o conservados | E32: 0.0034681869 | G32: =LEFT(H32,2) -> 16 | H32: 1621, 1622, 1623, 1629 | I32: Fabricación de productos de madera, productos de corcho, paja y materiales trenzables | J32: 0.0077252631 | M32: =J32 -> 0.0077252631 | N32: =M32/$M$56 -> 0.0077353773
C33: 21492 | D33: Melocotones, preparados o conservados | G33: =LEFT(H33,2) -> 17 | H33: 1701, 1702, 1709 | I33: Fabricación de papel y productos de papel | J33: 0.024913099 | K33: =J33 -> 0.024913099 | M33: =J33 -> 0.024913099 | N33: =M33/$M$56 -> 0.024945716
C34: 21493 | D34: Otras frutas, sin cocer o cocidos, congelados | G34: =LEFT(H34,2) -> 18 | H34: 1811, 1812, | I34: Impresión y actividades de servicios relacionados con la impresión y reproducción de grabaciones. | J34: 0.0093414024 | K34: =J34 -> 0.0093414024 | M34: =J34 -> 0.0093414024 | N34: =M34/$M$56 -> 0.0093536324
C35: 21494 | D35: Compotas, jaleas y mermeladas, purés y pastas de frutas u otros frutos | G35: =LEFT(H35,2) -> 19 | H35: 1910, 1920 | I35: Fabricación de coque y productos de la refinación del petróleo | J35: 0 | K35: =J35 -> 0
C36: 21495 | D36: Mantequilla de maní, pastas de almendra y otras mezclas de nueces y semillas tosdados, salados o preparados de otro modo n.c.p | G36: =LEFT(H36,2) -> 20 | H36: 2011 | I36: Fabricación de alcoholes | J36: 0.0065368306 | K36: =SUM(J36:J41) -> 0.082950426 | L36: =J36/SUM($J$36:$J$37,$J$39:$J$41) -> 0.078804063 | M36: =L36*$K$36 -> 0.0065368306 | N36: =M36/$M$56 -> 0.0065453888
C37: 21499 | D37: Otras preparaciones y conservas de frutas y nueces, n.c.p. | G37: =LEFT(H37,2) -> 20 | H37: 2012, 2021 | I37: Fabricación de abonos , compuestos de nitrógeno, plaguicidas y otros productos químicos de uso agropecuario | J37: 0.031290813 | L37: =J37/SUM($J$36:$J$37,$J$39:$J$41) -> 0.37722305 | M37: =L37*$K$36 -> 0.031290813 | N37: =M37/$M$56 -> 0.03133178
D38: Bebidas no alcohólicas | E38: 0.0018506947 | G38: =LEFT(H38,2) -> 20 | H38: 2013 | I38: Fabricación de plásticos y caucho sintético en formas primarias | J38: 0
C39: 24490A | D39: Otras bebidas calóricas no alcohólicas (Bebidas gaseosas, jugos y refrescos artificiales, bebidas deportivas, agua mineral con sabor) | E39: 0.0021471563 | G39: =LEFT(H39,2) -> 20 | H39: 2022 | I39: Fabricación de pinturas, barnices y productos de revestimiento similares, tintas de imprenta y masillas | J39: 0.0061612781 | L39: =J39/SUM($J$36:$J$37,$J$39:$J$41) -> 0.07427663 | M39: =L39*$K$36 -> 0.0061612781 | N39: =M39/$M$56 -> 0.0061693446
C40: 24410 | D40: Aguas embotelladas, no endulzadas ni saborizadas (Agua pura, agua con gas o mineral sin sabor, hielo) | G40: =LEFT(H40,2) -> 20 | H40: 2023 | I40: Fabricación de jabones y detergentes, preparados para limpiar y pulir, perfumes y preparados de tocador | J40: 0.026809279 | L40: =J40/SUM($J$36:$J$37,$J$39:$J$41) -> 0.3231964 | M40: =L40*$K$36 -> 0.026809279 | N40: =M40/$M$56 -> 0.026844379
...

Sheet Sheet6
A1: codigo | B1: nivel | C1: Codigo_CIIU_CCP | D1: Nombre | E1: Ponderacion
A2: C | B2: T | C2: C | D2: Industrias manufactureras | E2: =E3+E75+E81+E94+E106+E111+E121+E127+E130+E156+E160+E168+E180+E189+E197+E204+E209 -> 1
A3: C10 | B3: 2 | C3: 10 | D3: ELABORACIÓN DE PRODUCTOS ALIMENTICIOS | E3: 0.41720057
A4: C1010 | B4: 3 | C4: 1010 | D4: Elaboración y conservación de carne de ganado bovino | E4: =E5 -> 0.022490181
A5: C1010.21111 | B5: 4 | C5: 21111 | D5: Carne de ganado bovino, fresca o refrigerada | E5: 0.022490181
A6: C1010 | B6: 3 | C6: 1010 | D6: Elaboración y conservación de carne de ganado porcino | E6: =E7+E8 -> 0.0065073387
A7: C1010.21113 | B7: 4 | C7: 21113 | D7: Carne de cerdo, fresca o refrigerada | E7: 0.0057339459
A8: C1010.21119 | B8: 4 | C8: 21119 | D8: Otras carnes de mamíferos, fresca o refrigerada | E8: 0.00077339282
A9: C1010 | B9: 3 | C9: 1010 | D9: Elaboración y conservación de carne de aves de corral | E9: =E10+E11 -> 0.035805909
A10: C1010.21121 | B10: 4 | C10: 21121 | D10: Carne de pollo, fresca o refrigerada | E10: 0.021483545
A11: C1010.21160 | B11: 4 | C11: 21160 | D11: Despojos comestibles de aves de corral, frescos, refrigerados o congelados | E11: 0.014322363
A12: C1010 | B12: 3 | C12: 1010 | D12: Elaboración de productos cárnicos y elaboración de otros productos de origen animal n.c.p. | E12: =E13 -> 0.011751897
A13: C1010.21174 | B13: 4 | C13: 21174 | D13: Embutidos y productos similares de carne, despojos o sangre | E13: 0.011751897
A14: C1030 | B14: 3 | C14: 1030 | D14: Elaboración y conservación de frutas, legumbres y hortalizas | E14: =SUM(E15:E28) -> 0.016510051
A15: C1030.21431 | B15: 4 | C15: 21431 | D15: Jugo de naranja | E15: 0.0020992405
A16: C1030.21435 | B16: 4 | C16: 21435 | D16: Jugo de manzana | E16: 0.0020992405
A17: C1030.21439 | B17: 4 | C17: 21439 | D17: Otros jugos de frutas, n.c.p. | E17: 0.0020992405
A18: C1030.21311 | B18: 4 | C18: 21311 | D18: Frijoles estén o no desenvainados, cocidos en agua o vapor, Congelados. | E18: 0.001506621
A19: C1030.21395 | B19: 4 | C19: 21395 | D19: Frijoles, preparados o conservados, sin congelar. (excepto en vinagre o ácido acético). | E19: 0.001506621
A20: C1030.21399 | B20: 4 | C20: 21399 | D20: Otros vegetales y legumbres, conservados por algo que no sea vinagre, ácido acético o azúcar, n.c.p. | E20: 0.001506621
A21: C1030.21491 | B21: 4 | C21: 21491 | D21: Piñas, preparadas o conservados | E21: 0.00058597005
A22: C1030.21492 | B22: 4 | C22: 21492 | D22: Melocotones, preparados o conservados | E22: 0.00058597005
A23: C1030.21493 | B23: 4 | C23: 21493 | D23: Otras frutas, sin cocer o cocidos, congelados | E23: 0.00058597005
A24: C1030.21494 | B24: 4 | C24: 21494 | D24: Compotas, jaleas y mermeladas, purés y pastas de frutas u otros frutos | E24: 0.00058597005
A25: C1030.21495 | B25: 4 | C25: 21495 | D25: Mantequilla de maní, pastas de almendra y otras mezclas de nueces y semillas tosdados, salados o preparados de otro modo n.c.p | E25: 0.00058597005
A26: C1030.21499 | B26: 4 | C26: 21499 | D26: Otras preparaciones y conservas de frutas y nueces, n.c.p. | E26: 0.00058597005
A27: C1104.24490A | B27: 4 | C27: 24490A | D27: Otras bebidas calóricas no alcohólicas (Bebidas gaseosas, jugos y refrescos artificiales, bebidas deportivas, agua mineral con sabor) | E27: 0.0010883231
A28: C1030.24410 | B28: 4 | C28: 24410 | D28: Aguas embotelladas, no endulzadas ni saborizadas (Agua pura, agua con gas o mineral sin sabor, hielo) | E28: 0.0010883231
A29: C1040 | B29: 3 | C29: 1040 | D29: Elaboración de aceites y grasas de origen vegetal y animal | E29: =SUM(E30:E33) -> 0.057674403
A30: C1040.21535 | B30: 4 | C30: 21535 | D30: Aceite de palma, crudo | E30: 0.014418601
A31: C1040.21539 | B31: 4 | C31: 21539 | D31: Los demás aceites vegetales, crudo, n.c.p. | E31: 0.014418601
A32: C1040.21545 | B32: 4 | C32: 21545 | D32: Aceite de palma, refinado | E32: 0.014418601
A33: C1040.21549 | B33: 4 | C33: 21549 | D33: Otros aceites vegetales, refinados, n.c.p. | E33: 0.014418601
A34: C1050 | B34: 3 | C34: 1050 | D34: Elaboración de productos lácteos | E34: =SUM(E35:E40) -> 0.019659915
A35: C1050.22251 | B35: 4 | C35: 22251 | D35: Quesos de leche de bovino, frescos o procesados | E35: 0.0032766525
A36: C1050.22260 | B36: 4 | C36: 22260 | D36: Caseina | E36: 0.0032766525
A37: C1050.22270 | B37: 4 | C37: 22270 | D37: Helados y productos similares | E37: 0.0032766525
A38: C1050.22290 | B38: 4 | C38: 22290 | D38: Productos lácteos n.c.p. | E38: 0.0032766525
A39: C1050.22110 | B39: 4 | C39: 22110 | D39: Leche liquida procesada | E39: 0.0032766525
A40: C1050.22120 | B40: 4 | C40: 22120 | D40: Crema fresca | E40: 0.0032766525
...

Sheet Sheet4
A1: Clases
A2: 1010 | F2: 21111 | G2: =F2=F1 -> FALSE
A3: 1010 | F3: 21113
A4: 1010 | F4: 21119
A5: 1030 | F5: 21121 | G5: =F5=F4 -> FALSE
A6: 1040 | F6: 21174 | G6: =F6=F5 -> FALSE
A7: 1050 | F7: 21431 | G7: =F7=F6 -> FALSE
A8: 1061 | F8: 21435 | G8: =F8=F7 -> FALSE
A9: 1061 | F9: 21439
A10: 1061 | F10: 21311
A11: 1062 | F11: 21395 | G11: =F11=F10 -> FALSE
A12: 1071 | F12: 21399 | G12: =F12=F11 -> FALSE
A13: 1071 | F13: 21491
A14: 1072 | F14: 21492 | G14: =F14=F13 -> FALSE
A15: 1073 | F15: 21493 | G15: =F15=F14 -> FALSE
A16: 1074 | F16: 21494 | G16: =F16=F15 -> FALSE
A17: 1079 | F17: 21495 | G17: =F17=F16 -> FALSE
A18: 1080 | F18: 21499 | G18: =F18=F17 -> FALSE
A19: 1103 | F19: 24490 | G19: =F19=F18 -> FALSE
A20: 1104 | F20: 24410 | G20: =F20=F19 -> FALSE
A21: 1311 | F21: 21535 | G21: =F21=F20 -> FALSE
A22: 1391 | F22: 21539 | G22: =F22=F21 -> FALSE
A23: 1410 | F23: 21545 | G23: =F23=F22 -> FALSE
A24: 1520 | F24: 21549 | G24: =F24=F23 -> FALSE
A25: 1610 | F25: 22229 | G25: =F25=F24 -> FALSE
A26: 1621 | F26: 22251 | G26: =F26=F25 -> FALSE
A27: 1702 | F27: 22260 | G27: =F27=F26 -> FALSE
A28: 1811 | F28: 22270 | G28: =F28=F27 -> FALSE
A29: 2011 | F29: 22290 | G29: =F29=F28 -> FALSE
A30: 2021 | F30: 22110 | G30: =F30=F29 -> FALSE
A31: 2022 | F31: 22120 | G31: =F31=F30 -> FALSE
A32: 2023 | F32: 23110 | G32: =F32=F31 -> FALSE
A33: 2100 | F33: 23161 | G33: =F33=F32 -> FALSE
A34: 2220 | F34: 23140B | G34: =F34=F33 -> FALSE
A35: 2310 | F35: 23130 | G35: =F35=F34 -> FALSE
A36: 2392 | F36: 23140A | G36: =F36=F35 -> FALSE
A37: 2394 | F37: 23911 | G37: =F37=F36 -> FALSE
A38: 2395 | F38: 23912 | G38: =F38=F37 -> FALSE
A39: 2410 | F39: 23921 | G39: =F39=F38 -> FALSE
A40: 2511 | F40: 23928 | G40: =F40=F39 -> FALSE
...

Sheet Sheet5
A1: producto_codigo | B1: codigo
A2: C1010.21111 | B2: C1010.21111 | C2: 21111 | D2: C1010.21119 | F2: =RIGHT(B2,5) -> 21111 | G2: =F2=C2 -> TRUE
A3: C1010.21113 | B3: C1010.21113 | C3: 21113 | F3: =RIGHT(B3,5) -> 21113 | G3: =F3=C3 -> TRUE
A4: C1010.21119 | B4: C1010.21119 | C4: 21119 | F4: =RIGHT(B4,5) -> 21119 | G4: =F4=C4 -> TRUE
A5: C1010.21121 | B5: C1010.21121 | C5: 21121 | F5: =RIGHT(B5,5) -> 21121 | G5: =F5=C5 -> TRUE
A6: C1010.21174 | B6: C1010.21174 | C6: 21174 | D6: C1020.21221 | E6: Eliminar | F6: =RIGHT(B6,5) -> 21174 | G6: =F6=C6 -> TRUE
A7: C1030.21311 | B7: C1030.21311 | C7: 21311 | D7: C1020.21250 | E7: Eliminar | F7: =RIGHT(B7,5) -> 21311 | G7: =F7=C7 -> TRUE
A8: C1030.21395 | B8: C1030.21395 | C8: 21395 | F8: =RIGHT(B8,5) -> 21395 | G8: =F8=C8 -> TRUE
A9: C1030.21399 | B9: C1030.21399 | C9: 21399 | F9: =RIGHT(B9,5) -> 21399 | G9: =F9=C9 -> TRUE
A10: C1030.21431 | B10: C1030.21431 | C10: 21431 | F10: =RIGHT(B10,5) -> 21431 | G10: =F10=C10 -> TRUE
A11: C1030.21435 | B11: C1030.21435 | C11: 21435 | F11: =RIGHT(B11,5) -> 21435 | G11: =F11=C11 -> TRUE
A12: C1030.21439 | B12: C1030.21439 | C12: 21439 | F12: =RIGHT(B12,5) -> 21439 | G12: =F12=C12 -> TRUE
A13: agregado | B13: C1030.21491 | C13: 21491 | F13: =RIGHT(B13,5) -> 21491 | G13: =F13=C13 -> TRUE
A14: C1030.21492 | B14: C1030.21492 | C14: 21492 | F14: =RIGHT(B14,5) -> 21492 | G14: =F14=C14 -> TRUE
A15: C1030.21493 | B15: C1030.21493 | C15: 21493 | F15: =RIGHT(B15,5) -> 21493 | G15: =F15=C15 -> TRUE
A16: C1030.21494 | B16: C1030.21494 | C16: 21494 | F16: =RIGHT(B16,5) -> 21494 | G16: =F16=C16 -> TRUE
A17: C1030.21495 | B17: C1030.21495 | C17: 21495 | F17: =RIGHT(B17,5) -> 21495 | G17: =F17=C17 -> TRUE
A18: C1030.21499 | B18: C1030.21499 | C18: 21499 | F18: =RIGHT(B18,5) -> 21499 | G18: =F18=C18 -> TRUE
A19: C1040.21535 | B19: C1040.21535 | C19: 21535 | F19: =RIGHT(B19,5) -> 21535 | G19: =F19=C19 -> TRUE
... A23: C1050.22110 | B23: C1050.22110 | C23: 22110 | F23: =RIGHT(B23,5) -> 22110 | G23: =F23=C23 -> TRUE
A24: C1050.22120 | B24: C1050.22120 | C24: 22120 | F24: =RIGHT(B24,5) -> 22120 | G24: =F24=C24 -> TRUE | I24: C1040.21550
A25: C1050.22251 | B25: C1050.22251 | C25: 22251 | F25: =RIGHT(B25,5) -> 22251 | G25: =F25=C25 -> TRUE
A26: C1050.22260 | B26: C1050.22260 | C26: 22260 | F26: =RIGHT(B26,5) -> 22260 | G26: =F26=C26 -> TRUE
A27: C1050.22270 | B27: C1050.22270 | C27: 22270 | F27: =RIGHT(B27,5) -> 22270 | G27: =F27=C27 -> TRUE | J27: 23110
A28: C1050.22290 | B28: C1050.22290 | C28: 22290 | F28: =RIGHT(B28,5) -> 22290 | G28: =F28=C28 -> TRUE
A29: C1061.23110 | B29: C1061.23110 | C29: 23110 | F29: =RIGHT(B29,5) -> 23110 | G29: =F29=C29 -> TRUE
A30: C1061.23130 | B30: C1061.23130 | C30: 23130 | F30: =RIGHT(B30,5) -> 23130 | G30: =F30=C30 -> TRUE
A31: C1061.23140A | B31: C1061.23140A | C31: 23140A | D31: C1050.22229 | E31: Eliminado | F31: =RIGHT(B31,6) -> 23140A | G31: =F31=C31 -> TRUE
A32: C1061.23140B | B32: C1061.23140B | C32: 23140B | D32: C1061.39120 | E32: Eliminado | F32: =RIGHT(B32,6) -> 23140B | G32: =F32=C32 -> TRUE
A33: C1061.23161 | B33: C1061.23161 | C33: 23161 | D33: C1075.21176 | E33: Eliminado | F33: =RIGHT(B33,5) -> 23161 | G33: =F33=C33 -> TRUE
A34: C1071.23420 | B34: C1071.23420 | C34: 23420 | D34: C1079.23928 | E34: Eliminado | F34: =RIGHT(B34,5) -> 23420 | G34: =F34=C34 -> TRUE
A35: C1071.23430 | B35: C1071.23430 | C35: 23430 | D35: C1101.24131 | E35: Eliminado | F35: =RIGHT(B35,5) -> 23430 | G35: =F35=C35 -> TRUE
A36: C1071.23490A | B36: C1071.23490A | C36: 23490A | D36: C1391.27130 | E36: Eliminado | F36: =RIGHT(B36,6) -> 23490A | G36: =F36=C36 -> TRUE
A37: C1071.23490B | B37: C1071.23490B | C37: 23490B | D37: C1520.29310 | E37: Eliminado | F37: =RIGHT(B37,6) -> 23490B | G37: =F37=C37 -> TRUE
A38: C1072.23511 | B38: C1072.23511 | C38: 23511 | D38: C2011.34280 | E38: Eliminado | F38: =RIGHT(B38,5) -> 23511 | G38: =F38=C38 -> TRUE
A39: C1072.23520 | B39: C1072.23520 | C39: 23520 | D39: C2211.36120 | E39: Eliminado | F39: =RIGHT(B39,5) -> 23520 | G39: =F39=C39 -> TRUE
A40: C1073.23650 | B40: C1073.23650 | C40: 23650 | D40: C2219.36260 | E40: Eliminado | F40: =RIGHT(B40,5) -> 23650 | G40: =F40=C40 -> TRUE
A41: C1073.23660 | B41: C1073.23660 | C41: 23660 | D41: C2219.36270 | E41: Eliminado | F41: =RIGHT(B41,5) -> 23660 | G41: =F41=C41 -> TRUE
A42: C1073.23670 | B42: C1073.23670 | C42: 23670 | D42: C2220.36960 | E42: Eliminado | F42: =RIGHT(B42,5) -> 23670 | G42: =F42=C42 -> TRUE
A43: C1074.23710 | B43: C1074.23710 | C43: 23710 | D43: C2310.37113 | E43: Eliminado | F43: =RIGHT(B43,5) -> 23710 | G43: =F43=C43 -> TRUE | L43: C1072.23540
...

Sheet consultas
A1: P102 | B1: Servicios de comercio | C1: P5401 | D1: Servicios de Comercio
A2: P103 | B2: Mantenimiento y reparación de vehículos automotores y motocicletas | C2: P5402 | D2: Mantenimiento y Reparación de Vehículos automotores y Motocicletas
A3: P104 | B3: Servicio de transporte de pasajeros por vía terrestre | C3: P5501 | D3: Servicio de transporte de pasajeros por vía terrestre
A4: P105 | B4: Servicio de transporte de carga por vía terrestre | C4: P5502 | D4: Servicio de transporte de carga por vía terrestre
